Workbook
Name ASSM_DevRatioCap: 'RBC Assumptions'!$C$74
Name ASSM_DevRatioCap: #REF!
Name ASSM_EG_Cap: 'RBC Assumptions'!$C$69
Name ASSM_EG_MultPrem: 'RBC Assumptions'!$C$71
Name ASSM_EG_MultPrem: #REF!
Name ASSM_EG_MultRes: 'RBC Assumptions'!$C$70
Name ASSM_EG_MultRes: #REF!
Name ASSM_EG_Threshold: 'RBC Assumptions'!$C$68
Name ASSM_GWP_3YrAvgGrowth: 'RBC Assumptions'!$C$85
Name ASSM_LLAERatioCap: 'RBC Assumptions'!$C$75
Name ASSM_LLAERatioCap: #REF!
Name ASSM_LS_Assumed: 'RBC Assumptions'!$C$73
Name ASSM_LS_Assumed: #REF!
Name ASSM_LS_Direct: 'RBC Assumptions'!$C$72
Name ASSM_LS_Direct: #REF!
Name ASSM_ProvReinsPC: 'RBC Assumptions'!$C$77
Name ASSM_R1_Agency: 'RBC Assumptions'!$C$6
Name ASSM_R1_Agency: #REF!
Name ASSM_R1_Cash: 'RBC Assumptions'!$C$14
Name ASSM_R1_Cash: #REF!
Name ASSM_R1_Class01: 'RBC Assumptions'!$C$7
Name ASSM_R1_Class01: #REF!
Name ASSM_R1_Class02: 'RBC Assumptions'!$C$8
Name ASSM_R1_Class02: #REF!
Name ASSM_R1_Class03: 'RBC Assumptions'!$C$9
Name ASSM_R1_Class03: #REF!
Name ASSM_R1_Class04: 'RBC Assumptions'!$C$10
Name ASSM_R1_Class04: #REF!
Name ASSM_R1_Class05: 'RBC Assumptions'!$C$11
Name ASSM_R1_Class05: #REF!
Name ASSM_R1_Class06: 'RBC Assumptions'!$C$12
Name ASSM_R1_Class06: #REF!
Name ASSM_R1_Collateral: 'RBC Assumptions'!$C$16
Name ASSM_R1_Collateral: #REF!
Name ASSM_R1_Mortgage: 'RBC Assumptions'!$C$13
Name ASSM_R1_Mortgage: #REF!
Name ASSM_R1_ShortTerm: 'RBC Assumptions'!$C$15
Name ASSM_R1_ShortTerm: #REF!
Name ASSM_R1_USGov: 'RBC Assumptions'!$C$5
Name ASSM_R1_USGov: #REF!
Name ASSM_R2_CommonStock: 'RBC Assumptions'!$C$28
Name ASSM_R2_CommonStock: #REF!
Name ASSM_R2_MoneyMkt: 'RBC Assumptions'!$C$27
Name ASSM_R2_MoneyMkt: #REF!
Name ASSM_R2_PrefClass01: 'RBC Assumptions'!$C$21
Name ASSM_R2_PrefClass02: 'RBC Assumptions'!$C$22
Name ASSM_R2_PrefClass02: #REF!
Name ASSM_R2_PrefClass03: 'RBC Assumptions'!$C$23
Name ASSM_R2_PrefClass04: 'RBC Assumptions'!$C$24
Name ASSM_R2_PrefClass05: 'RBC Assumptions'!$C$25
Name ASSM_R2_PrefClass06: 'RBC Assumptions'!$C$26
Name ASSM_R2_RealEstate: 'RBC Assumptions'!$C$29
Name ASSM_R2_RealEstate: #REF!
Name ASSM_R2_Receivables: 'RBC Assumptions'!$C$31
Name ASSM_R2_SchedBA: 'RBC Assumptions'!$C$30
Name ASSM_R2_SchedBA: #REF!
Name ASSM_R3_FedTax: 'RBC Assumptions'!$C$38
Name ASSM_R3_FedTax: #REF!
Name ASSM_R3_IIAccrued: 'RBC Assumptions'!$C$37
Name ASSM_R3_IIAccrued: #REF!

Sheet README
B2: Legend
B3: Inputs
B4: Formula from another tab
B5: Formula from same tab
B7: Disclaimer
B8: This financial model is meant to be a proxy, to provide directional results and RBC figures
B10: Tab | C10: Inputs
B11: Ann Summary | C11: -
B12: Program | C12: Program level UW assumptions and projections
B13: Program Qtrly | C13: Ability to override assumptions by quarter
B14: Prem Earn | C14: -
B15: Loss Proj | C15: -
B16: OpEx | C16: Headcount, Comp, G&A expense
B17: Inc Stmt | C17: Other Income, Income Adj., Invest. Yield/Expense, and Tax Rate
B18: Bal Sheet | C18: Starting Surplus, Future Paid in Capital, R3 Misc Credit Items
B19: IRIS | C19: -
B20: R1 | C20: -
B21: R2 | C21: -
... B32: Liquidity [Hidden] | C32: Not used for RBC, and not updated

Sheet Program Inputs
A1: PROGRAM ASSUMPTIONS
A2: Units: $ in thousands ($000s), rates as decimals
A4: START YEAR | B4: 2026
A5: START QTR | B5: 2
A7: PROGRAM ASSUMPTIONS
A8: Program ID | B8: Program Name | C8: GWP Year 1 | D8: GWP Year 2 | E8: GWP Year 3 | F8: GWP Year 4 | G8: GWP Year 5 | H8: LLAE Ratio | I8: QS Cession (%) | J8: Gross Comm (%) | K8: Fronting Fee (%) | L8: Sched P LOB | M8: Ann. Stmt LOB | N8: Avg Policy Term | O8: Loss Dev Pattern | P8: Effective Date | Q8: Status | R8: Reinsurer ID | S8: Reinsurer Name
A9: P001 | B9: VI: Sports Refund | C9: 12000 | D9: 15000 | E9: 18000 | F9: 21000 | G9: 24000 | H9: 0.1 | I9: 0 | J9: 0.5 | K9: 0.05 | L9: Special Liability | M9: Other liability—claims-made | N9: 2 | O9: Property_1 | P9: 46174 | Q9: Active
A10: P002 | B10: VI: Event | C10: 5000 | D10: 7000 | E10: 9000 | F10: 11000 | G10: 13000 | H10: 0.3 | I10: 0.8 | J10: 0.3 | K10: 0.05 | L10: Special Liability | M10: Other liability—claims-made | N10: 3 | O10: Property_1 | P10: 46174 | Q10: Active
A11: P003 | B11: VI: Pet | C11: 5000 | D11: 7000 | E11: 9000 | F11: 11000 | G11: 13000 | H11: 0.5 | I11: 0.8 | J11: 0.25 | K11: 0.05 | L11: Special Property | M11: Pet Insurance Plans | N11: 12 | O11: Property_1 | P11: 46174 | Q11: Active
A12: P004 | B12: VI: Tuition Reimbursement | C12: 5000 | D12: 7000 | E12: 9000 | F12: 11000 | G12: 13000 | H12: 0.2 | I12: 0.5 | J12: 0.4 | K12: 0.05 | L12: Special Liability | M12: Other liability—claims-made | N12: 6 | O12: Property_1 | P12: 46174 | Q12: Active
A13: P005 | B13: Greenlight MGAs | C13: 10000 | D13: 20000 | E13: 40000 | F13: 60000 | G13: 80000 | H13: 0.6 | I13: 0.9 | J13: 0.35 | K13: 0.05 | L13: Commercial Multi Peril | M13: Inland Marine | N13: 12 | O13: Property_3 | P13: 46266 | Q13: Pipeline
A14: P006 | B14: Gigsafe | C14: 2500 | D14: 3500 | E14: 5000 | F14: 7500 | G14: 10000 | H14: 0.6 | I14: 0.9 | J14: 0.45 | K14: 0.05 | L14: Workers' Compensation | M14: Workers’ compensation | N14: 12 | O14: Workers' Compensation | P14: 46266 | Q14: Pending
A15: P007 | B15: Leaselock | C15: 10000 | D15: 15000 | E15: 20000 | F15: 25000 | G15: 30000 | H15: 0.6 | I15: 0.9 | J15: 0.45 | K15: 0.05 | L15: Special Property | M15: Commercial multiple peril (non-liability portion) | N15: 12 | O15: Property_2 | P15: 46266 | Q15: Pipeline
A16: P008 | B16: Surety | C16: 0 | D16: 5000 | E16: 7000 | F16: 10000 | G16: 15000 | H16: 0.6 | I16: 0.7 | J16: 0.25 | K16: 0.05 | L16: Fidelity and Surety | M16: Surety | N16: 12 | O16: Fidelity and Surety | P16: 46478 | Q16: Pipeline
A17: P009 | B17: Fronting Property | C17: 10000 | D17: 20000 | E17: 30000 | F17: 40000 | G17: 50000 | H17: 0.6 | I17: 1 | J17: 0.25 | K17: 0.05 | L17: Commercial Multi Peril | M17: Inland Marine | N17: 12 | O17: Property_2 | P17: 46266 | Q17: Pending
A18: P010 | B18: Fronting Casualty | C18: 0 | D18: 0 | E18: 10000 | F18: 20000 | G18: 40000 | H18: 0.6 | I18: 1 | J18: 0.25 | K18: 0.05 | L18: Other Liability Occurrence | M18: Other liability—occurrence | N18: 12 | O18: Casualty_2 | P18: 46753 | Q18: Pipeline
A19: P011 | B19: Short-tail | C19: 0 | D19: 10000 | E19: 20000 | F19: 40000 | G19: 60000 | H19: 0.6 | I19: 0.8 | J19: 0.3 | K19: 0.05 | L19: Homeowners and Farmowners | M19: Fire | N19: 12 | O19: Homeowners and Farmowners | P19: 46388 | Q19: Pipeline
A20: P012 | B20: Long-tail | C20: 0 | D20: 0 | E20: 0 | F20: 10000 | G20: 20000 | H20: 0.6 | I20: 0.8 | J20: 0.3 | K20: 0.05 | L20: Other Liability Occurrence | M20: Other liability—occurrence | N20: 12 | O20: Property_2 | P20: 47119 | Q20: Pipeline
A21: P013 | B21: Other | C21: 1000 | D21: 5000 | E21: 10000 | F21: 20000 | G21: 30000 | H21: 0.5 | I21: 0.5 | J21: 0.25 | K21: 0.05 | L21: Special Property | M21: Homeowners multiple peril | N21: 12 | O21: Property_1 | P21: 46266 | Q21: Pipeline
A22: P014 | C22: 0 | D22: 0 | E22: 0 | F22: 0 | G22: 0 | H22: 0 | I22: 0 | J22: 0 | K22: 0.05
A23: P015 | C23: 0 | D23: 0 | E23: 0 | F23: 0 | G23: 0 | H23: 0 | I23: 0 | J23: 0 | K23: 0.05
A24: P016 | C24: 0 | D24: 0 | E24: 0 | F24: 0 | G24: 0 | H24: 0 | I24: 0 | J24: 0 | K24: 0.05
A25: P017 | C25: 0 | D25: 0 | E25: 0 | F25: 0 | G25: 0 | H25: 0 | I25: 0 | J25: 0 | K25: 0.05
A26: P018 | C26: 0 | D26: 0 | E26: 0 | F26: 0 | G26: 0 | H26: 0 | I26: 0 | J26: 0 | K26: 0.05
A27: P019 | C27: 0 | D27: 0 | E27: 0 | F27: 0 | G27: 0 | H27: 0 | I27: 0 | J27: 0 | K27: 0.05
A28: P020 | C28: 0 | D28: 0 | E28: 0 | F28: 0 | G28: 0 | H28: 0 | I28: 0 | J28: 0 | K28: 0.05
A29: Total | C29: =SUM(C9:C28) -> 60500 | D29: =SUM(D9:D28) -> 114500 | E29: =SUM(E9:E28) -> 187000 | F29: =SUM(F9:F28) -> 286500 | G29: =SUM(G9:G28) -> 398000

Sheet Program Qtrly
A1: PROGRAM ASSUMPTIONS
A2: Units: $ in thousands ($000s), rates as decimals
D4: ='Program Inputs'!B4 -> 2026 | E4: =IF(D5=4,D4+1,D4) -> 2026 | F4: =IF(E5=4,E4+1,E4) -> 2026 | G4: =IF(F5=4,F4+1,F4) -> 2027 | H4: =IF(G5=4,G4+1,G4) -> 2027 | I4: =IF(H5=4,H4+1,H4) -> 2027 | J4: =IF(I5=4,I4+1,I4) -> 2027 | K4: =IF(J5=4,J4+1,J4) -> 2028 | L4: =IF(K5=4,K4+1,K4) -> 2028 | ... W4: =IF(V5=4,V4+1,V4) -> 2031
A5: PROGRAM PROJECTIONS | D5: ='Program Inputs'!B5 -> 2 | E5: =IF(D5=4,1,D5+1) -> 3 | F5: =IF(E5=4,1,E5+1) -> 4 | G5: =IF(F5=4,1,F5+1) -> 1 | H5: =IF(G5=4,1,G5+1) -> 2 | I5: =IF(H5=4,1,H5+1) -> 3 | J5: =IF(I5=4,1,I5+1) -> 4 | K5: =IF(J5=4,1,J5+1) -> 1 | L5: =IF(K5=4,1,K5+1) -> 2 | ... W5: =IF(V5=4,1,V5+1) -> 1
A6: Program ID | B6: Program ID | C6: Metric | D6: =D4&" Q"&D5 -> 2026 Q2 | E6: =E4&" Q"&E5 -> 2026 Q3 | F6: =F4&" Q"&F5 -> 2026 Q4 | G6: =G4&" Q"&G5 -> 2027 Q1 | H6: =H4&" Q"&H5 -> 2027 Q2 | I6: =I4&" Q"&I5 -> 2027 Q3 | J6: =J4&" Q"&J5 -> 2027 Q4 | K6: =K4&" Q"&K5 -> 2028 Q1 | ... W6: =W4&" Q"&W5 -> 2031 Q1
A7: P001 | B7: =INDEX('Program Inputs'!$B$9:$B$28,MATCH(A7,'Program Inputs'!$A$9:$A$28,0)) -> VI: Sports Refund | C7: GWP | D7: =SUMIFS('Program Inputs'!$C:$C,'Program Inputs'!$A:$A,'Program Qtrly'!$A7)/4 -> 3000 | E7: =SUMIFS('Program Inputs'!$C:$C,'Program Inputs'!$A:$A,'Program Qtrly'!$A7)/4 -> 3000 | F7: =SUMIFS('Program Inputs'!$C:$C,'Program Inputs'!$A:$A,'Program Qtrly'!$A7)/4 -> 3000 | G7: =SUMIFS('Program Inputs'!$C:$C,'Program Inputs'!$A:$A,'Program Qtrly'!$A7)/4 -> 3000 | H7: =SUMIFS('Program Inputs'!$D:$D,'Program Inputs'!$A:$A,'Program Qtrly'!$A7)/4 -> 3750 | I7: =SUMIFS('Program Inputs'!$D:$D,'Program Inputs'!$A:$A,'Program Qtrly'!$A7)/4 -> 3750 | J7: =SUMIFS('Program Inputs'!$D:$D,'Program Inputs'!$A:$A,'Program Qtrly'!$A7)/4 -> 3750 | K7: =SUMIFS('Program Inputs'!$D:$D,'Program Inputs'!$A:$A,'Program Qtrly'!$A7)/4 -> 3750 | L7: =SUMIFS('Program Inputs'!$E:$E,'Program Inputs'!$A:$A,'Program Qtrly'!$A7)/4 -> 4500 | M7: =SUMIFS('Program Inputs'!$E:$E,'Program Inputs'!$A:$A,'Program Qtrly'!$A7)/4 -> 4500 | N7: =SUMIFS('Program Inputs'!$E:$E,'Program Inputs'!$A:$A,'Program Qtrly'!$A7)/4 -> 4500 | O7: =SUMIFS('Program Inputs'!$E:$E,'Program Inputs'!$A:$A,'Program Qtrly'!$A7)/4 -> 4500 | P7: =SUMIFS('Program Inputs'!$F:$F,'Program Inputs'!$A:$A,'Program Qtrly'!$A7)/4 -> 5250 | Q7: =SUMIFS('Program Inputs'!$F:$F,'Program Inputs'!$A:$A,'Program Qtrly'!$A7)/4 -> 5250 | R7: =SUMIFS('Program Inputs'!$F:$F,'Program Inputs'!$A:$A,'Program Qtrly'!$A7)/4 -> 5250 | S7: =SUMIFS('Program Inputs'!$F:$F,'Program Inputs'!$A:$A,'Program Qtrly'!$A7)/4 -> 5250 | T7: =SUMIFS('Program Inputs'!$G:$G,'Program Inputs'!$A:$A,'Program Qtrly'!$A7)/4 -> 6000 | U7: =SUMIFS('Program Inputs'!$G:$G,'Program Inputs'!$A:$A,'Program Qtrly'!$A7)/4 -> 6000 | V7: =SUMIFS('Program Inputs'!$G:$G,'Program Inputs'!$A:$A,'Program Qtrly'!$A7)/4 -> 6000 | W7: =SUMIFS('Program Inputs'!$G:$G,'Program Inputs'!$A:$A,'Program Qtrly'!$A7)/4 -> 6000
A8: P001 | B8: =INDEX('Program Inputs'!$B$9:$B$28,MATCH(A8,'Program Inputs'!$A$9:$A$28,0)) -> VI: Sports Refund | C8: LLAE Ratio | D8: =SUMIFS('Program Inputs'!$H:$H,'Program Inputs'!$A:$A,'Program Qtrly'!$A8) -> 0.1 | E8: =D8 -> 0.1 | F8: =E8 -> 0.1 | G8: =F8 -> 0.1 | H8: =G8 -> 0.1 | I8: =H8 -> 0.1 | J8: =I8 -> 0.1 | K8: =J8 -> 0.1 | L8: =K8 -> 0.1 | ... W8: =V8 -> 0.1
A9: P001 | B9: =INDEX('Program Inputs'!$B$9:$B$28,MATCH(A9,'Program Inputs'!$A$9:$A$28,0)) -> VI: Sports Refund | C9: QS Cession (%) | D9: =SUMIFS('Program Inputs'!$I:$I,'Program Inputs'!$A:$A,'Program Qtrly'!$A9) -> 0 | E9: =D9 -> 0 | F9: =E9 -> 0 | G9: =F9 -> 0 | H9: =G9 -> 0 | I9: =H9 -> 0 | J9: =I9 -> 0 | K9: =J9 -> 0 | L9: =K9 -> 0 | ... W9: =V9 -> 0
A10: P001 | B10: =INDEX('Program Inputs'!$B$9:$B$28,MATCH(A10,'Program Inputs'!$A$9:$A$28,0)) -> VI: Sports Refund | C10: Gross Comm (%) | D10: =SUMIFS('Program Inputs'!$J:$J,'Program Inputs'!$A:$A,'Program Qtrly'!$A10) -> 0.5 | E10: =D10 -> 0.5 | F10: =E10 -> 0.5 | G10: =F10 -> 0.5 | H10: =G10 -> 0.5 | I10: =H10 -> 0.5 | J10: =I10 -> 0.5 | K10: =J10 -> 0.5 | L10: =K10 -> 0.5 | ... W10: =V10 -> 0.5
A11: P001 | B11: =INDEX('Program Inputs'!$B$9:$B$28,MATCH(A11,'Program Inputs'!$A$9:$A$28,0)) -> VI: Sports Refund | C11: Fronting Fee (%) | D11: =SUMIFS('Program Inputs'!$K:$K,'Program Inputs'!$A:$A,'Program Qtrly'!$A11) -> 0.05 | E11: =D11 -> 0.05 | F11: =E11 -> 0.05 | G11: =F11 -> 0.05 | H11: =G11 -> 0.05 | I11: =H11 -> 0.05 | J11: =I11 -> 0.05 | K11: =J11 -> 0.05 | L11: =K11 -> 0.05 | ... W11: =V11 -> 0.05
A12: P001 | B12: =INDEX('Program Inputs'!$B$9:$B$28,MATCH(A12,'Program Inputs'!$A$9:$A$28,0)) -> VI: Sports Refund | C12: Ceding Comm (%) | D12: =D10+D11 -> 0.55 | E12: =E10+E11 -> 0.55 | F12: =F10+F11 -> 0.55 | G12: =G10+G11 -> 0.55 | H12: =H10+H11 -> 0.55 | I12: =I10+I11 -> 0.55 | J12: =J10+J11 -> 0.55 | K12: =K10+K11 -> 0.55 | ... W12: =W10+W11 -> 0.55
A13: P001 | B13: =INDEX('Program Inputs'!$B$9:$B$28,MATCH(A13,'Program Inputs'!$A$9:$A$28,0)) -> VI: Sports Refund | C13: Net Comm Exps | D13: =D7*(1-D9)*D10 -> 1500 | E13: =E7*(1-E9)*E10 -> 1500 | F13: =F7*(1-F9)*F10 -> 1500 | G13: =G7*(1-G9)*G10 -> 1500 | H13: =H7*(1-H9)*H10 -> 1875 | I13: =I7*(1-I9)*I10 -> 1875 | J13: =J7*(1-J9)*J10 -> 1875 | K13: =K7*(1-K9)*K10 -> 1875 | ... W13: =W7*(1-W9)*W10 -> 3000
A14: P001 | B14: =INDEX('Program Inputs'!$B$9:$B$28,MATCH(A14,'Program Inputs'!$A$9:$A$28,0)) -> VI: Sports Refund | C14: Fronting Fees | D14: =D11*D16 -> 0 | E14: =E11*E16 -> 0 | F14: =F11*F16 -> 0 | G14: =G11*G16 -> 0 | H14: =H11*H16 -> 0 | I14: =I11*I16 -> 0 | J14: =J11*J16 -> 0 | K14: =K11*K16 -> 0 | ... W14: =W11*W16 -> 0
A15: P001 | B15: =INDEX('Program Inputs'!$B$9:$B$28,MATCH(A15,'Program Inputs'!$A$9:$A$28,0)) -> VI: Sports Refund | C15: NWP | D15: =D7*(1-D9) -> 3000 | E15: =E7*(1-E9) -> 3000 | F15: =F7*(1-F9) -> 3000 | G15: =G7*(1-G9) -> 3000 | H15: =H7*(1-H9) -> 3750 | I15: =I7*(1-I9) -> 3750 | J15: =J7*(1-J9) -> 3750 | K15: =K7*(1-K9) -> 3750 | ... W15: =W7*(1-W9) -> 6000
A16: P001 | B16: =INDEX('Program Inputs'!$B$9:$B$28,MATCH(A16,'Program Inputs'!$A$9:$A$28,0)) -> VI: Sports Refund | C16: Ceded WP | D16: =D7*D9 -> 0 | E16: =E7*E9 -> 0 | F16: =F7*F9 -> 0 | G16: =G7*G9 -> 0 | H16: =H7*H9 -> 0 | I16: =I7*I9 -> 0 | J16: =J7*J9 -> 0 | K16: =K7*K9 -> 0 | ... W16: =W7*W9 -> 0
A17: P001 | B17: =INDEX('Program Inputs'!$B$9:$B$28,MATCH(A17,'Program Inputs'!$A$9:$A$28,0)) -> VI: Sports Refund | C17: GEP | D17: ='Prem Earn'!X44 -> 2000 | E17: ='Prem Earn'!Y44 -> 3000 | F17: ='Prem Earn'!Z44 -> 3000 | G17: ='Prem Earn'!AA44 -> 3000 | H17: ='Prem Earn'!AB44 -> 3500 | I17: ='Prem Earn'!AC44 -> 3750 | J17: ='Prem Earn'!AD44 -> 3750 | K17: ='Prem Earn'!AE44 -> 3750 | ... W17: ='Prem Earn'!AQ44 -> 6000
A18: P001 | B18: =INDEX('Program Inputs'!$B$9:$B$28,MATCH(A18,'Program Inputs'!$A$9:$A$28,0)) -> VI: Sports Refund | C18: Cuml GWP | D18: =SUM($D7:D7) -> 3000 | E18: =SUM($D7:E7) -> 6000 | F18: =SUM($D7:F7) -> 9000 | G18: =SUM($D7:G7) -> 12000 | H18: =SUM($D7:H7) -> 15750 | I18: =SUM($D7:I7) -> 19500 | J18: =SUM($D7:J7) -> 23250 | K18: =SUM($D7:K7) -> 27000 | ... W18: =SUM($D7:W7) -> 90000
A19: P001 | B19: =INDEX('Program Inputs'!$B$9:$B$28,MATCH(A19,'Program Inputs'!$A$9:$A$28,0)) -> VI: Sports Refund | C19: Cuml GEP | D19: =SUM($D17:D17) -> 2000 | E19: =SUM($D17:E17) -> 5000 | F19: =SUM($D17:F17) -> 8000 | G19: =SUM($D17:G17) -> 11000 | H19: =SUM($D17:H17) -> 14500 | I19: =SUM($D17:I17) -> 18250 | J19: =SUM($D17:J17) -> 22000 | K19: =SUM($D17:K17) -> 25750 | ... W19: =SUM($D17:W17) -> 88000
A20: P001 | B20: =INDEX('Program Inputs'!$B$9:$B$28,MATCH(A20,'Program Inputs'!$A$9:$A$28,0)) -> VI: Sports Refund | C20: Gross UPR | D20: =D18-D19 -> 1000 | E20: =E18-E19 -> 1000 | F20: =F18-F19 -> 1000 | G20: =G18-G19 -> 1000 | H20: =H18-H19 -> 1250 | I20: =I18-I19 -> 1250 | J20: =J18-J19 -> 1250 | K20: =K18-K19 -> 1250 | ... W20: =W18-W19 -> 2000
A21: P001 | B21: =INDEX('Program Inputs'!$B$9:$B$28,MATCH(A21,'Program Inputs'!$A$9:$A$28,0)) -> VI: Sports Refund | C21: Ceded UPR | D21: =D20-D26 -> 0 | E21: =E20-E26 -> 0 | F21: =F20-F26 -> 0 | G21: =G20-G26 -> 0 | H21: =H20-H26 -> 0 | I21: =I20-I26 -> 0 | J21: =J20-J26 -> 0 | K21: =K20-K26 -> 0 | ... W21: =W20-W26 -> 0
A22: P001 | B22: =INDEX('Program Inputs'!$B$9:$B$28,MATCH(A22,'Program Inputs'!$A$9:$A$28,0)) -> VI: Sports Refund | C22: NEP | D22: ='Prem Earn'!B44 -> 2000 | E22: ='Prem Earn'!C44 -> 3000 | F22: ='Prem Earn'!D44 -> 3000 | G22: ='Prem Earn'!E44 -> 3000 | H22: ='Prem Earn'!F44 -> 3500 | I22: ='Prem Earn'!G44 -> 3750 | J22: ='Prem Earn'!H44 -> 3750 | K22: ='Prem Earn'!I44 -> 3750 | ... W22: ='Prem Earn'!U44 -> 6000
A23: P001 | B23: =INDEX('Program Inputs'!$B$9:$B$28,MATCH(A23,'Program Inputs'!$A$9:$A$28,0)) -> VI: Sports Refund | C23: Net Losses & LAE | D23: =D22*D9 -> 0 | E23: =E22*E9 -> 0 | F23: =F22*F9 -> 0 | G23: =G22*G9 -> 0 | H23: =H22*H9 -> 0 | I23: =I22*I9 -> 0 | J23: =J22*J9 -> 0 | K23: =K22*K9 -> 0 | ... W23: =W22*W9 -> 0
A24: P001 | B24: =INDEX('Program Inputs'!$B$9:$B$28,MATCH(A24,'Program Inputs'!$A$9:$A$28,0)) -> VI: Sports Refund | C24: Cuml NWP | D24: =SUM($D15:D15) -> 3000 | E24: =SUM($D15:E15) -> 6000 | F24: =SUM($D15:F15) -> 9000 | G24: =SUM($D15:G15) -> 12000 | H24: =SUM($D15:H15) -> 15750 | I24: =SUM($D15:I15) -> 19500 | J24: =SUM($D15:J15) -> 23250 | K24: =SUM($D15:K15) -> 27000 | ... W24: =SUM($D15:W15) -> 90000
A25: P001 | B25: =INDEX('Program Inputs'!$B$9:$B$28,MATCH(A25,'Program Inputs'!$A$9:$A$28,0)) -> VI: Sports Refund | C25: Cuml NEP | D25: =SUM($D22:D22) -> 2000 | E25: =SUM($D22:E22) -> 5000 | F25: =SUM($D22:F22) -> 8000 | G25: =SUM($D22:G22) -> 11000 | H25: =SUM($D22:H22) -> 14500 | I25: =SUM($D22:I22) -> 18250 | J25: =SUM($D22:J22) -> 22000 | K25: =SUM($D22:K22) -> 25750 | ... W25: =SUM($D22:W22) -> 88000
A26: P001 | B26: =INDEX('Program Inputs'!$B$9:$B$28,MATCH(A26,'Program Inputs'!$A$9:$A$28,0)) -> VI: Sports Refund | C26: Net UPR | D26: =D24-D25 -> 1000 | E26: =E24-E25 -> 1000 | F26: =F24-F25 -> 1000 | G26: =G24-G25 -> 1000 | H26: =H24-H25 -> 1250 | I26: =I24-I25 -> 1250 | J26: =J24-J25 -> 1250 | K26: =K24-K25 -> 1250 | ... W26: =W24-W25 -> 2000
A27: P002 | B27: =INDEX('Program Inputs'!$B$9:$B$28,MATCH(A27,'Program Inputs'!$A$9:$A$28,0)) -> VI: Event | C27: GWP | D27: =SUMIFS('Program Inputs'!$C:$C,'Program Inputs'!$A:$A,'Program Qtrly'!$A27)/4 -> 1250 | E27: =SUMIFS('Program Inputs'!$C:$C,'Program Inputs'!$A:$A,'Program Qtrly'!$A27)/4 -> 1250 | F27: =SUMIFS('Program Inputs'!$C:$C,'Program Inputs'!$A:$A,'Program Qtrly'!$A27)/4 -> 1250 | G27: =SUMIFS('Program Inputs'!$C:$C,'Program Inputs'!$A:$A,'Program Qtrly'!$A27)/4 -> 1250 | H27: =SUMIFS('Program Inputs'!$D:$D,'Program Inputs'!$A:$A,'Program Qtrly'!$A27)/4 -> 1750 | I27: =SUMIFS('Program Inputs'!$D:$D,'Program Inputs'!$A:$A,'Program Qtrly'!$A27)/4 -> 1750 | J27: =SUMIFS('Program Inputs'!$D:$D,'Program Inputs'!$A:$A,'Program Qtrly'!$A27)/4 -> 1750 | K27: =SUMIFS('Program Inputs'!$D:$D,'Program Inputs'!$A:$A,'Program Qtrly'!$A27)/4 -> 1750 | L27: =SUMIFS('Program Inputs'!$E:$E,'Program Inputs'!$A:$A,'Program Qtrly'!$A27)/4 -> 2250 | M27: =SUMIFS('Program Inputs'!$E:$E,'Program Inputs'!$A:$A,'Program Qtrly'!$A27)/4 -> 2250 | N27: =SUMIFS('Program Inputs'!$E:$E,'Program Inputs'!$A:$A,'Program Qtrly'!$A27)/4 -> 2250 | O27: =SUMIFS('Program Inputs'!$E:$E,'Program Inputs'!$A:$A,'Program Qtrly'!$A27)/4 -> 2250 | P27: =SUMIFS('Program Inputs'!$F:$F,'Program Inputs'!$A:$A,'Program Qtrly'!$A27)/4 -> 2750 | Q27: =SUMIFS('Program Inputs'!$F:$F,'Program Inputs'!$A:$A,'Program Qtrly'!$A27)/4 -> 2750 | R27: =SUMIFS('Program Inputs'!$F:$F,'Program Inputs'!$A:$A,'Program Qtrly'!$A27)/4 -> 2750 | S27: =SUMIFS('Program Inputs'!$F:$F,'Program Inputs'!$A:$A,'Program Qtrly'!$A27)/4 -> 2750 | T27: =SUMIFS('Program Inputs'!$G:$G,'Program Inputs'!$A:$A,'Program Qtrly'!$A27)/4 -> 3250 | U27: =SUMIFS('Program Inputs'!$G:$G,'Program Inputs'!$A:$A,'Program Qtrly'!$A27)/4 -> 3250 | V27: =SUMIFS('Program Inputs'!$G:$G,'Program Inputs'!$A:$A,'Program Qtrly'!$A27)/4 -> 3250 | W27: =SUMIFS('Program Inputs'!$G:$G,'Program Inputs'!$A:$A,'Program Qtrly'!$A27)/4 -> 3250
A28: P002 | B28: =INDEX('Program Inputs'!$B$9:$B$28,MATCH(A28,'Program Inputs'!$A$9:$A$28,0)) -> VI: Event | C28: LLAE Ratio | D28: =SUMIFS('Program Inputs'!$H:$H,'Program Inputs'!$A:$A,'Program Qtrly'!$A28) -> 0.3 | E28: =D28 -> 0.3 | F28: =E28 -> 0.3 | G28: =F28 -> 0.3 | H28: =G28 -> 0.3 | I28: =H28 -> 0.3 | J28: =I28 -> 0.3 | K28: =J28 -> 0.3 | L28: =K28 -> 0.3 | ... W28: =V28 -> 0.3
A29: P002 | B29: =INDEX('Program Inputs'!$B$9:$B$28,MATCH(A29,'Program Inputs'!$A$9:$A$28,0)) -> VI: Event | C29: QS Cession (%) | D29: =SUMIFS('Program Inputs'!$I:$I,'Program Inputs'!$A:$A,'Program Qtrly'!$A29) -> 0.8 | E29: =D29 -> 0.8 | F29: =E29 -> 0.8 | G29: =F29 -> 0.8 | H29: =G29 -> 0.8 | I29: =H29 -> 0.8 | J29: =I29 -> 0.8 | K29: =J29 -> 0.8 | L29: =K29 -> 0.8 | ... W29: =V29 -> 0.8
A30: P002 | B30: =INDEX('Program Inputs'!$B$9:$B$28,MATCH(A30,'Program Inputs'!$A$9:$A$28,0)) -> VI: Event | C30: Gross Comm (%) | D30: =SUMIFS('Program Inputs'!$J:$J,'Program Inputs'!$A:$A,'Program Qtrly'!$A30) -> 0.3 | E30: =D30 -> 0.3 | F30: =E30 -> 0.3 | G30: =F30 -> 0.3 | H30: =G30 -> 0.3 | I30: =H30 -> 0.3 | J30: =I30 -> 0.3 | K30: =J30 -> 0.3 | L30: =K30 -> 0.3 | ... W30: =V30 -> 0.3
A31: P002 | B31: =INDEX('Program Inputs'!$B$9:$B$28,MATCH(A31,'Program Inputs'!$A$9:$A$28,0)) -> VI: Event | C31: Fronting Fee (%) | D31: =SUMIFS('Program Inputs'!$K:$K,'Program Inputs'!$A:$A,'Program Qtrly'!$A31) -> 0.05 | E31: =D31 -> 0.05 | F31: =E31 -> 0.05 | G31: =F31 -> 0.05 | H31: =G31 -> 0.05 | I31: =H31 -> 0.05 | J31: =I31 -> 0.05 | K31: =J31 -> 0.05 | L31: =K31 -> 0.05 | ... W31: =V31 -> 0.05
A32: P002 | B32: =INDEX('Program Inputs'!$B$9:$B$28,MATCH(A32,'Program Inputs'!$A$9:$A$28,0)) -> VI: Event | C32: Ceding Comm (%) | D32: =D30+D31 -> 0.35 | E32: =E30+E31 -> 0.35 | F32: =F30+F31 -> 0.35 | G32: =G30+G31 -> 0.35 | H32: =H30+H31 -> 0.35 | I32: =I30+I31 -> 0.35 | J32: =J30+J31 -> 0.35 | K32: =K30+K31 -> 0.35 | ... W32: =W30+W31 -> 0.35
A33: P002 | B33: =INDEX('Program Inputs'!$B$9:$B$28,MATCH(A33,'Program Inputs'!$A$9:$A$28,0)) -> VI: Event | C33: Net Comm Exps | D33: =D27*(1-D29)*D30 -> 75 | E33: =E27*(1-E29)*E30 -> 75 | F33: =F27*(1-F29)*F30 -> 75 | G33: =G27*(1-G29)*G30 -> 75 | H33: =H27*(1-H29)*H30 -> 105 | I33: =I27*(1-I29)*I30 -> 105 | J33: =J27*(1-J29)*J30 -> 105 | K33: =K27*(1-K29)*K30 -> 105 | ... W33: =W27*(1-W29)*W30 -> 195
A34: P002 | B34: =INDEX('Program Inputs'!$B$9:$B$28,MATCH(A34,'Program Inputs'!$A$9:$A$28,0)) -> VI: Event | C34: Fronting Fees | D34: =D31*D36 -> 50 | E34: =E31*E36 -> 50 | F34: =F31*F36 -> 50 | G34: =G31*G36 -> 50 | H34: =H31*H36 -> 70 | I34: =I31*I36 -> 70 | J34: =J31*J36 -> 70 | K34: =K31*K36 -> 70 | ... W34: =W31*W36 -> 130
A35: P002 | B35: =INDEX('Program Inputs'!$B$9:$B$28,MATCH(A35,'Program Inputs'!$A$9:$A$28,0)) -> VI: Event | C35: NWP | D35: =D27*(1-D29) -> 250 | E35: =E27*(1-E29) -> 250 | F35: =F27*(1-F29) -> 250 | G35: =G27*(1-G29) -> 250 | H35: =H27*(1-H29) -> 350 | I35: =I27*(1-I29) -> 350 | J35: =J27*(1-J29) -> 350 | K35: =K27*(1-K29) -> 350 | ... W35: =W27*(1-W29) -> 650
A36: P002 | B36: =INDEX('Program Inputs'!$B$9:$B$28,MATCH(A36,'Program Inputs'!$A$9:$A$28,0)) -> VI: Event | C36: Ceded WP | D36: =D27*D29 -> 1000 | E36: =E27*E29 -> 1000 | F36: =F27*F29 -> 1000 | G36: =G27*G29 -> 1000 | H36: =H27*H29 -> 1400 | I36: =I27*I29 -> 1400 | J36: =J27*J29 -> 1400 | K36: =K27*K29 -> 1400 | ... W36: =W27*W29 -> 2600
A37: P002 | B37: =INDEX('Program Inputs'!$B$9:$B$28,MATCH(A37,'Program Inputs'!$A$9:$A$28,0)) -> VI: Event | C37: GEP | D37: ='Prem Earn'!X60 -> 625 | E37: ='Prem Earn'!Y60 -> 1250 | F37: ='Prem Earn'!Z60 -> 1250 | G37: ='Prem Earn'!AA60 -> 1250 | H37: ='Prem Earn'!AB60 -> 1500 | I37: ='Prem Earn'!AC60 -> 1750 | J37: ='Prem Earn'!AD60 -> 1750 | K37: ='Prem Earn'!AE60 -> 1750 | ... W37: ='Prem Earn'!AQ60 -> 3250
A38: P002 | B38: =INDEX('Program Inputs'!$B$9:$B$28,MATCH(A38,'Program Inputs'!$A$9:$A$28,0)) -> VI: Event | C38: Cuml GWP | D38: =SUM($D27:D27) -> 1250 | E38: =SUM($D27:E27) -> 2500 | F38: =SUM($D27:F27) -> 3750 | G38: =SUM($D27:G27) -> 5000 | H38: =SUM($D27:H27) -> 6750 | I38: =SUM($D27:I27) -> 8500 | J38: =SUM($D27:J27) -> 10250 | K38: =SUM($D27:K27) -> 12000 | ... W38: =SUM($D27:W27) -> 45000
A39: P002 | B39: =INDEX('Program Inputs'!$B$9:$B$28,MATCH(A39,'Program Inputs'!$A$9:$A$28,0)) -> VI: Event | C39: Cuml GEP | D39: =SUM($D37:D37) -> 625 | E39: =SUM($D37:E37) -> 1875 | F39: =SUM($D37:F37) -> 3125 | G39: =SUM($D37:G37) -> 4375 | H39: =SUM($D37:H37) -> 5875 | I39: =SUM($D37:I37) -> 7625 | J39: =SUM($D37:J37) -> 9375 | K39: =SUM($D37:K37) -> 11125 | ... W39: =SUM($D37:W37) -> 43375
A40: P002 | B40: =INDEX('Program Inputs'!$B$9:$B$28,MATCH(A40,'Program Inputs'!$A$9:$A$28,0)) -> VI: Event | C40: Gross UPR | D40: =D38-D39 -> 625 | E40: =E38-E39 -> 625 | F40: =F38-F39 -> 625 | G40: =G38-G39 -> 625 | H40: =H38-H39 -> 875 | I40: =I38-I39 -> 875 | J40: =J38-J39 -> 875 | K40: =K38-K39 -> 875 | ... W40: =W38-W39 -> 1625
A41: P002 | B41: =INDEX('Program Inputs'!$B$9:$B$28,MATCH(A41,'Program Inputs'!$A$9:$A$28,0)) -> VI: Event | C41: Ceded UPR | D41: =D40-D46 -> 500 | E41: =E40-E46 -> 500 | F41: =F40-F46 -> 500 | G41: =G40-G46 -> 500 | H41: =H40-H46 -> 700 | I41: =I40-I46 -> 700 | J41: =J40-J46 -> 700 | K41: =K40-K46 -> 700 | ... W41: =W40-W46 -> 1300
...

Sheet Prem Earn
A1: PREMIUM EARNING
A2: Units: $ in thousands ($000s), rates as decimals
A4: EARNING PATTERN | B4: Policy Qtr Age | D4: Assumes even writing throughout the quarter
A5: Policy Duration | B5: 3 | C5: =B5+3 -> 6 | D5: =C5+3 -> 9 | E5: =D5+3 -> 12 | F5: =E5+3 -> 15 | G5: =F5+3 -> 18 | H5: =G5+3 -> 21 | I5: =H5+3 -> 24 | J5: =I5+3 -> 27 | K5: CHECK
A6: 1 | B6: =5/6 -> 0.83333333 | C6: =1/6 -> 0.16666667 | K6: =SUM(B6:J6) -> 1
A7: 2 | B7: =2/3 -> 0.66666667 | C7: =1/3 -> 0.33333333 | K7: =SUM(B7:J7) -> 1
A8: 3 | B8: =1/2 -> 0.5 | C8: 0.5 | K8: =SUM(B8:J8) -> 1
A9: 6 | B9: =1/4 -> 0.25 | C9: 0.5 | D9: 0.25 | K9: =SUM(B9:J9) -> 1
A10: 12 | B10: =1/8 -> 0.125 | C10: 0.25 | D10: 0.25 | E10: 0.25 | F10: 0.125 | K10: =SUM(B10:J10) -> 1
A11: 18 | B11: =1/12 -> 0.083333333 | C11: =B11*2 -> 0.16666667 | D11: =C11 -> 0.16666667 | E11: =D11 -> 0.16666667 | F11: =E11 -> 0.16666667 | G11: =F11 -> 0.16666667 | H11: =1/12 -> 0.083333333 | K11: =SUM(B11:J11) -> 1
A12: 24 | B12: =1/16 -> 0.0625 | C12: =B12*2 -> 0.125 | D12: =C12 -> 0.125 | E12: =D12 -> 0.125 | F12: =E12 -> 0.125 | G12: =F12 -> 0.125 | H12: =G12 -> 0.125 | I12: =H12 -> 0.125 | J12: =1/16 -> 0.0625 | K12: =SUM(B12:J12) -> 1
A15: TOTAL ALL PROGRAMS | W15: TOTAL ALL PROGRAMS
A16: Net Earned Premium | W16: Gross Earned Premium
A18: Age | B18: ='Program Qtrly'!D$6 -> 2026 Q2 | C18: ='Program Qtrly'!E$6 -> 2026 Q3 | D18: ='Program Qtrly'!F$6 -> 2026 Q4 | E18: ='Program Qtrly'!G$6 -> 2027 Q1 | F18: ='Program Qtrly'!H$6 -> 2027 Q2 | G18: ='Program Qtrly'!I$6 -> 2027 Q3 | H18: ='Program Qtrly'!J$6 -> 2027 Q4 | I18: ='Program Qtrly'!K$6 -> 2028 Q1 | ... U18: ='Program Qtrly'!W$6 -> 2031 Q1 | W18: Age | X18: ='Program Qtrly'!D$6 -> 2026 Q2 | Y18: ='Program Qtrly'!E$6 -> 2026 Q3 | Z18: ='Program Qtrly'!F$6 -> 2026 Q4 | AA18: ='Program Qtrly'!G$6 -> 2027 Q1 | AB18: ='Program Qtrly'!H$6 -> 2027 Q2 | AC18: ='Program Qtrly'!I$6 -> 2027 Q3 | AD18: ='Program Qtrly'!J$6 -> 2027 Q4 | AE18: ='Program Qtrly'!K$6 -> 2028 Q1 | ... AQ18: ='Program Qtrly'!W$6 -> 2031 Q1
A19: 3 | B19: =B35+B51+B67+B83+B99+B115+B131+B147+B163+B179+B195+B211+B227+B243+B259+B275+B291+B307+B323+B339 -> 2398.4375 | C19: =C35+C51+C67+C83+C99+C115+C131+C147+C163+C179+C195+C211+C227+C243+C259+C275+C291+C307+C323+C339 -> 2398.4375 | D19: =D35+D51+D67+D83+D99+D115+D131+D147+D163+D179+D195+D211+D227+D243+D259+D275+D291+D307+D323+D339 -> 2398.4375 | E19: =E35+E51+E67+E83+E99+E115+E131+E147+E163+E179+E195+E211+E227+E243+E259+E275+E291+E307+E323+E339 -> 2398.4375 | F19: =F35+F51+F67+F83+F99+F115+F131+F147+F163+F179+F195+F211+F227+F243+F259+F275+F291+F307+F323+F339 -> 3245.3125 | G19: =G35+G51+G67+G83+G99+G115+G131+G147+G163+G179+G195+G211+G227+G243+G259+G275+G291+G307+G323+G339 -> 3245.3125 | H19: =H35+H51+H67+H83+H99+H115+H131+H147+H163+H179+H195+H211+H227+H243+H259+H275+H291+H307+H323+H339 -> 3245.3125 | I19: =I35+I51+I67+I83+I99+I115+I131+I147+I163+I179+I195+I211+I227+I243+I259+I275+I291+I307+I323+I339 -> 3245.3125 | ... U19: =U35+U51+U67+U83+U99+U115+U131+U147+U163+U179+U195+U211+U227+U243+U259+U275+U291+U307+U323+U339 -> 6296.875 | W19: 3 | X19: =X35+X51+X67+X83+X99+X115+X131+X147+X163+X179+X195+X211+X227+X243+X259+X275+X291+X307+X323+X339 -> 4140.625 | Y19: =Y35+Y51+Y67+Y83+Y99+Y115+Y131+Y147+Y163+Y179+Y195+Y211+Y227+Y243+Y259+Y275+Y291+Y307+Y323+Y339 -> 4140.625 | Z19: =Z35+Z51+Z67+Z83+Z99+Z115+Z131+Z147+Z163+Z179+Z195+Z211+Z227+Z243+Z259+Z275+Z291+Z307+Z323+Z339 -> 4140.625 | AA19: =AA35+AA51+AA67+AA83+AA99+AA115+AA131+AA147+AA163+AA179+AA195+AA211+AA227+AA243+AA259+AA275+AA291+AA307+AA323+AA339 -> 4140.625 | AB19: =AB35+AB51+AB67+AB83+AB99+AB115+AB131+AB147+AB163+AB179+AB195+AB211+AB227+AB243+AB259+AB275+AB291+AB307+AB323+AB339 -> 6484.375 | AC19: =AC35+AC51+AC67+AC83+AC99+AC115+AC131+AC147+AC163+AC179+AC195+AC211+AC227+AC243+AC259+AC275+AC291+AC307+AC323+AC339 -> 6484.375 | AD19: =AD35+AD51+AD67+AD83+AD99+AD115+AD131+AD147+AD163+AD179+AD195+AD211+AD227+AD243+AD259+AD275+AD291+AD307+AD323+AD339 -> 6484.375 | AE19: =AE35+AE51+AE67+AE83+AE99+AE115+AE131+AE147+AE163+AE179+AE195+AE211+AE227+AE243+AE259+AE275+AE291+AE307+AE323+AE339 -> 6484.375 | ... AQ19: =AQ35+AQ51+AQ67+AQ83+AQ99+AQ115+AQ131+AQ147+AQ163+AQ179+AQ195+AQ211+AQ227+AQ243+AQ259+AQ275+AQ291+AQ307+AQ323+AQ339 -> 17312.5
A20: =A19+3 -> 6 | B20: =B36+B52+B68+B84+B100+B116+B132+B148+B164+B180+B196+B212+B228+B244+B260+B276+B292+B308+B324+B340 -> 1671.875 | C20: =C36+C52+C68+C84+C100+C116+C132+C148+C164+C180+C196+C212+C228+C244+C260+C276+C292+C308+C324+C340 -> 1671.875 | D20: =D36+D52+D68+D84+D100+D116+D132+D148+D164+D180+D196+D212+D228+D244+D260+D276+D292+D308+D324+D340 -> 1671.875 | E20: =E36+E52+E68+E84+E100+E116+E132+E148+E164+E180+E196+E212+E228+E244+E260+E276+E292+E308+E324+E340 -> 1671.875 | F20: =F36+F52+F68+F84+F100+F116+F132+F148+F164+F180+F196+F212+F228+F244+F260+F276+F292+F308+F324+F340 -> 2565.625 | G20: =G36+G52+G68+G84+G100+G116+G132+G148+G164+G180+G196+G212+G228+G244+G260+G276+G292+G308+G324+G340 -> 2565.625 | H20: =H36+H52+H68+H84+H100+H116+H132+H148+H164+H180+H196+H212+H228+H244+H260+H276+H292+H308+H324+H340 -> 2565.625 | I20: =I36+I52+I68+I84+I100+I116+I132+I148+I164+I180+I196+I212+I228+I244+I260+I276+I292+I308+I324+I340 -> 2565.625 | ... U20: =U36+U52+U68+U84+U100+U116+U132+U148+U164+U180+U196+U212+U228+U244+U260+U276+U292+U308+U324+U340 -> 6268.75 | W20: =W19+3 -> 6 | X20: =X36+X52+X68+X84+X100+X116+X132+X148+X164+X180+X196+X212+X228+X244+X260+X276+X292+X308+X324+X340 -> 4656.25 | Y20: =Y36+Y52+Y68+Y84+Y100+Y116+Y132+Y148+Y164+Y180+Y196+Y212+Y228+Y244+Y260+Y276+Y292+Y308+Y324+Y340 -> 4656.25 | Z20: =Z36+Z52+Z68+Z84+Z100+Z116+Z132+Z148+Z164+Z180+Z196+Z212+Z228+Z244+Z260+Z276+Z292+Z308+Z324+Z340 -> 4656.25 | AA20: =AA36+AA52+AA68+AA84+AA100+AA116+AA132+AA148+AA164+AA180+AA196+AA212+AA228+AA244+AA260+AA276+AA292+AA308+AA324+AA340 -> 4656.25 | AB20: =AB36+AB52+AB68+AB84+AB100+AB116+AB132+AB148+AB164+AB180+AB196+AB212+AB228+AB244+AB260+AB276+AB292+AB308+AB324+AB340 -> 8343.75 | AC20: =AC36+AC52+AC68+AC84+AC100+AC116+AC132+AC148+AC164+AC180+AC196+AC212+AC228+AC244+AC260+AC276+AC292+AC308+AC324+AC340 -> 8343.75 | AD20: =AD36+AD52+AD68+AD84+AD100+AD116+AD132+AD148+AD164+AD180+AD196+AD212+AD228+AD244+AD260+AD276+AD292+AD308+AD324+AD340 -> 8343.75 | AE20: =AE36+AE52+AE68+AE84+AE100+AE116+AE132+AE148+AE164+AE180+AE196+AE212+AE228+AE244+AE260+AE276+AE292+AE308+AE324+AE340 -> 8343.75 | ... AQ20: =AQ36+AQ52+AQ68+AQ84+AQ100+AQ116+AQ132+AQ148+AQ164+AQ180+AQ196+AQ212+AQ228+AQ244+AQ260+AQ276+AQ292+AQ308+AQ324+AQ340 -> 27000
A21: =A20+3 -> 9 | B21: =B37+B53+B69+B85+B101+B117+B133+B149+B165+B181+B197+B213+B229+B245+B261+B277+B293+B309+B325+B341 -> 390.625 | C21: =C37+C53+C69+C85+C101+C117+C133+C149+C165+C181+C197+C213+C229+C245+C261+C277+C293+C309+C325+C341 -> 390.625 | D21: =D37+D53+D69+D85+D101+D117+D133+D149+D165+D181+D197+D213+D229+D245+D261+D277+D293+D309+D325+D341 -> 390.625 | E21: =E37+E53+E69+E85+E101+E117+E133+E149+E165+E181+E197+E213+E229+E245+E261+E277+E293+E309+E325+E341 -> 390.625 | F21: =F37+F53+F69+F85+F101+F117+F133+F149+F165+F181+F197+F213+F229+F245+F261+F277+F293+F309+F325+F341 -> 921.875 | G21: =G37+G53+G69+G85+G101+G117+G133+G149+G165+G181+G197+G213+G229+G245+G261+G277+G293+G309+G325+G341 -> 921.875 | H21: =H37+H53+H69+H85+H101+H117+H133+H149+H165+H181+H197+H213+H229+H245+H261+H277+H293+H309+H325+H341 -> 921.875 | I21: =I37+I53+I69+I85+I101+I117+I133+I149+I165+I181+I197+I213+I229+I245+I261+I277+I293+I309+I325+I341 -> 921.875 | ... U21: =U37+U53+U69+U85+U101+U117+U133+U149+U165+U181+U197+U213+U229+U245+U261+U277+U293+U309+U325+U341 -> 3537.5 | W21: =W20+3 -> 9 | X21: =X37+X53+X69+X85+X101+X117+X133+X149+X165+X181+X197+X213+X229+X245+X261+X277+X293+X309+X325+X341 -> 2718.75 | Y21: =Y37+Y53+Y69+Y85+Y101+Y117+Y133+Y149+Y165+Y181+Y197+Y213+Y229+Y245+Y261+Y277+Y293+Y309+Y325+Y341 -> 2718.75 | Z21: =Z37+Z53+Z69+Z85+Z101+Z117+Z133+Z149+Z165+Z181+Z197+Z213+Z229+Z245+Z261+Z277+Z293+Z309+Z325+Z341 -> 2718.75 | AA21: =AA37+AA53+AA69+AA85+AA101+AA117+AA133+AA149+AA165+AA181+AA197+AA213+AA229+AA245+AA261+AA277+AA293+AA309+AA325+AA341 -> 2718.75 | AB21: =AB37+AB53+AB69+AB85+AB101+AB117+AB133+AB149+AB165+AB181+AB197+AB213+AB229+AB245+AB261+AB277+AB293+AB309+AB325+AB341 -> 5781.25 | AC21: =AC37+AC53+AC69+AC85+AC101+AC117+AC133+AC149+AC165+AC181+AC197+AC213+AC229+AC245+AC261+AC277+AC293+AC309+AC325+AC341 -> 5781.25 | AD21: =AD37+AD53+AD69+AD85+AD101+AD117+AD133+AD149+AD165+AD181+AD197+AD213+AD229+AD245+AD261+AD277+AD293+AD309+AD325+AD341 -> 5781.25 | AE21: =AE37+AE53+AE69+AE85+AE101+AE117+AE133+AE149+AE165+AE181+AE197+AE213+AE229+AE245+AE261+AE277+AE293+AE309+AE325+AE341 -> 5781.25 | ... AQ21: =AQ37+AQ53+AQ69+AQ85+AQ101+AQ117+AQ133+AQ149+AQ165+AQ181+AQ197+AQ213+AQ229+AQ245+AQ261+AQ277+AQ293+AQ309+AQ325+AQ341 -> 22562.5
A22: =A21+3 -> 12 | B22: =B38+B54+B70+B86+B102+B118+B134+B150+B166+B182+B198+B214+B230+B246+B262+B278+B294+B310+B326+B342 -> 234.375 | C22: =C38+C54+C70+C86+C102+C118+C134+C150+C166+C182+C198+C214+C230+C246+C262+C278+C294+C310+C326+C342 -> 234.375 | D22: =D38+D54+D70+D86+D102+D118+D134+D150+D166+D182+D198+D214+D230+D246+D262+D278+D294+D310+D326+D342 -> 234.375 | E22: =E38+E54+E70+E86+E102+E118+E134+E150+E166+E182+E198+E214+E230+E246+E262+E278+E294+E310+E326+E342 -> 234.375 | F22: =F38+F54+F70+F86+F102+F118+F134+F150+F166+F182+F198+F214+F230+F246+F262+F278+F294+F310+F326+F342 -> 703.125 | G22: =G38+G54+G70+G86+G102+G118+G134+G150+G166+G182+G198+G214+G230+G246+G262+G278+G294+G310+G326+G342 -> 703.125 | H22: =H38+H54+H70+H86+H102+H118+H134+H150+H166+H182+H198+H214+H230+H246+H262+H278+H294+H310+H326+H342 -> 703.125 | I22: =I38+I54+I70+I86+I102+I118+I134+I150+I166+I182+I198+I214+I230+I246+I262+I278+I294+I310+I326+I342 -> 703.125 | ... U22: =U38+U54+U70+U86+U102+U118+U134+U150+U166+U182+U198+U214+U230+U246+U262+U278+U294+U310+U326+U342 -> 3131.25 | W22: =W21+3 -> 12 | X22: =X38+X54+X70+X86+X102+X118+X134+X150+X166+X182+X198+X214+X230+X246+X262+X278+X294+X310+X326+X342 -> 2406.25 | Y22: =Y38+Y54+Y70+Y86+Y102+Y118+Y134+Y150+Y166+Y182+Y198+Y214+Y230+Y246+Y262+Y278+Y294+Y310+Y326+Y342 -> 2406.25 | Z22: =Z38+Z54+Z70+Z86+Z102+Z118+Z134+Z150+Z166+Z182+Z198+Z214+Z230+Z246+Z262+Z278+Z294+Z310+Z326+Z342 -> 2406.25 | AA22: =AA38+AA54+AA70+AA86+AA102+AA118+AA134+AA150+AA166+AA182+AA198+AA214+AA230+AA246+AA262+AA278+AA294+AA310+AA326+AA342 -> 2406.25 | AB22: =AB38+AB54+AB70+AB86+AB102+AB118+AB134+AB150+AB166+AB182+AB198+AB214+AB230+AB246+AB262+AB278+AB294+AB310+AB326+AB342 -> 5343.75 | AC22: =AC38+AC54+AC70+AC86+AC102+AC118+AC134+AC150+AC166+AC182+AC198+AC214+AC230+AC246+AC262+AC278+AC294+AC310+AC326+AC342 -> 5343.75 | AD22: =AD38+AD54+AD70+AD86+AD102+AD118+AD134+AD150+AD166+AD182+AD198+AD214+AD230+AD246+AD262+AD278+AD294+AD310+AD326+AD342 -> 5343.75 | AE22: =AE38+AE54+AE70+AE86+AE102+AE118+AE134+AE150+AE166+AE182+AE198+AE214+AE230+AE246+AE262+AE278+AE294+AE310+AE326+AE342 -> 5343.75 | ... AQ22: =AQ38+AQ54+AQ70+AQ86+AQ102+AQ118+AQ134+AQ150+AQ166+AQ182+AQ198+AQ214+AQ230+AQ246+AQ262+AQ278+AQ294+AQ310+AQ326+AQ342 -> 21750
A23: =A22+3 -> 15 | B23: =B39+B55+B71+B87+B103+B119+B135+B151+B167+B183+B199+B215+B231+B247+B263+B279+B295+B311+B327+B343 -> 117.1875 | C23: =C39+C55+C71+C87+C103+C119+C135+C151+C167+C183+C199+C215+C231+C247+C263+C279+C295+C311+C327+C343 -> 117.1875 | D23: =D39+D55+D71+D87+D103+D119+D135+D151+D167+D183+D199+D215+D231+D247+D263+D279+D295+D311+D327+D343 -> 117.1875 | E23: =E39+E55+E71+E87+E103+E119+E135+E151+E167+E183+E199+E215+E231+E247+E263+E279+E295+E311+E327+E343 -> 117.1875 | F23: =F39+F55+F71+F87+F103+F119+F135+F151+F167+F183+F199+F215+F231+F247+F263+F279+F295+F311+F327+F343 -> 351.5625 | G23: =G39+G55+G71+G87+G103+G119+G135+G151+G167+G183+G199+G215+G231+G247+G263+G279+G295+G311+G327+G343 -> 351.5625 | H23: =H39+H55+H71+H87+H103+H119+H135+H151+H167+H183+H199+H215+H231+H247+H263+H279+H295+H311+H327+H343 -> 351.5625 | I23: =I39+I55+I71+I87+I103+I119+I135+I151+I167+I183+I199+I215+I231+I247+I263+I279+I295+I311+I327+I343 -> 351.5625 | ... U23: =U39+U55+U71+U87+U103+U119+U135+U151+U167+U183+U199+U215+U231+U247+U263+U279+U295+U311+U327+U343 -> 1565.625 | W23: =W22+3 -> 15 | X23: =X39+X55+X71+X87+X103+X119+X135+X151+X167+X183+X199+X215+X231+X247+X263+X279+X295+X311+X327+X343 -> 1203.125 | Y23: =Y39+Y55+Y71+Y87+Y103+Y119+Y135+Y151+Y167+Y183+Y199+Y215+Y231+Y247+Y263+Y279+Y295+Y311+Y327+Y343 -> 1203.125 | Z23: =Z39+Z55+Z71+Z87+Z103+Z119+Z135+Z151+Z167+Z183+Z199+Z215+Z231+Z247+Z263+Z279+Z295+Z311+Z327+Z343 -> 1203.125 | AA23: =AA39+AA55+AA71+AA87+AA103+AA119+AA135+AA151+AA167+AA183+AA199+AA215+AA231+AA247+AA263+AA279+AA295+AA311+AA327+AA343 -> 1203.125 | AB23: =AB39+AB55+AB71+AB87+AB103+AB119+AB135+AB151+AB167+AB183+AB199+AB215+AB231+AB247+AB263+AB279+AB295+AB311+AB327+AB343 -> 2671.875 | AC23: =AC39+AC55+AC71+AC87+AC103+AC119+AC135+AC151+AC167+AC183+AC199+AC215+AC231+AC247+AC263+AC279+AC295+AC311+AC327+AC343 -> 2671.875 | AD23: =AD39+AD55+AD71+AD87+AD103+AD119+AD135+AD151+AD167+AD183+AD199+AD215+AD231+AD247+AD263+AD279+AD295+AD311+AD327+AD343 -> 2671.875 | AE23: =AE39+AE55+AE71+AE87+AE103+AE119+AE135+AE151+AE167+AE183+AE199+AE215+AE231+AE247+AE263+AE279+AE295+AE311+AE327+AE343 -> 2671.875 | ... AQ23: =AQ39+AQ55+AQ71+AQ87+AQ103+AQ119+AQ135+AQ151+AQ167+AQ183+AQ199+AQ215+AQ231+AQ247+AQ263+AQ279+AQ295+AQ311+AQ327+AQ343 -> 10875
A24: =A23+3 -> 18 | B24: =B40+B56+B72+B88+B104+B120+B136+B152+B168+B184+B200+B216+B232+B248+B264+B280+B296+B312+B328+B344 -> 0 | C24: =C40+C56+C72+C88+C104+C120+C136+C152+C168+C184+C200+C216+C232+C248+C264+C280+C296+C312+C328+C344 -> 0 | D24: =D40+D56+D72+D88+D104+D120+D136+D152+D168+D184+D200+D216+D232+D248+D264+D280+D296+D312+D328+D344 -> 0 | E24: =E40+E56+E72+E88+E104+E120+E136+E152+E168+E184+E200+E216+E232+E248+E264+E280+E296+E312+E328+E344 -> 0 | F24: =F40+F56+F72+F88+F104+F120+F136+F152+F168+F184+F200+F216+F232+F248+F264+F280+F296+F312+F328+F344 -> 0 | G24: =G40+G56+G72+G88+G104+G120+G136+G152+G168+G184+G200+G216+G232+G248+G264+G280+G296+G312+G328+G344 -> 0 | H24: =H40+H56+H72+H88+H104+H120+H136+H152+H168+H184+H200+H216+H232+H248+H264+H280+H296+H312+H328+H344 -> 0 | I24: =I40+I56+I72+I88+I104+I120+I136+I152+I168+I184+I200+I216+I232+I248+I264+I280+I296+I312+I328+I344 -> 0 | ... U24: =U40+U56+U72+U88+U104+U120+U136+U152+U168+U184+U200+U216+U232+U248+U264+U280+U296+U312+U328+U344 -> 0 | W24: =W23+3 -> 18 | X24: =X40+X56+X72+X88+X104+X120+X136+X152+X168+X184+X200+X216+X232+X248+X264+X280+X296+X312+X328+X344 -> 0 | Y24: =Y40+Y56+Y72+Y88+Y104+Y120+Y136+Y152+Y168+Y184+Y200+Y216+Y232+Y248+Y264+Y280+Y296+Y312+Y328+Y344 -> 0 | Z24: =Z40+Z56+Z72+Z88+Z104+Z120+Z136+Z152+Z168+Z184+Z200+Z216+Z232+Z248+Z264+Z280+Z296+Z312+Z328+Z344 -> 0 | AA24: =AA40+AA56+AA72+AA88+AA104+AA120+AA136+AA152+AA168+AA184+AA200+AA216+AA232+AA248+AA264+AA280+AA296+AA312+AA328+AA344 -> 0 | AB24: =AB40+AB56+AB72+AB88+AB104+AB120+AB136+AB152+AB168+AB184+AB200+AB216+AB232+AB248+AB264+AB280+AB296+AB312+AB328+AB344 -> 0 | AC24: =AC40+AC56+AC72+AC88+AC104+AC120+AC136+AC152+AC168+AC184+AC200+AC216+AC232+AC248+AC264+AC280+AC296+AC312+AC328+AC344 -> 0 | AD24: =AD40+AD56+AD72+AD88+AD104+AD120+AD136+AD152+AD168+AD184+AD200+AD216+AD232+AD248+AD264+AD280+AD296+AD312+AD328+AD344 -> 0 | AE24: =AE40+AE56+AE72+AE88+AE104+AE120+AE136+AE152+AE168+AE184+AE200+AE216+AE232+AE248+AE264+AE280+AE296+AE312+AE328+AE344 -> 0 | ... AQ24: =AQ40+AQ56+AQ72+AQ88+AQ104+AQ120+AQ136+AQ152+AQ168+AQ184+AQ200+AQ216+AQ232+AQ248+AQ264+AQ280+AQ296+AQ312+AQ328+AQ344 -> 0
A25: =A24+3 -> 21 | B25: =B41+B57+B73+B89+B105+B121+B137+B153+B169+B185+B201+B217+B233+B249+B265+B281+B297+B313+B329+B345 -> 0 | C25: =C41+C57+C73+C89+C105+C121+C137+C153+C169+C185+C201+C217+C233+C249+C265+C281+C297+C313+C329+C345 -> 0 | D25: =D41+D57+D73+D89+D105+D121+D137+D153+D169+D185+D201+D217+D233+D249+D265+D281+D297+D313+D329+D345 -> 0 | E25: =E41+E57+E73+E89+E105+E121+E137+E153+E169+E185+E201+E217+E233+E249+E265+E281+E297+E313+E329+E345 -> 0 | F25: =F41+F57+F73+F89+F105+F121+F137+F153+F169+F185+F201+F217+F233+F249+F265+F281+F297+F313+F329+F345 -> 0 | G25: =G41+G57+G73+G89+G105+G121+G137+G153+G169+G185+G201+G217+G233+G249+G265+G281+G297+G313+G329+G345 -> 0 | H25: =H41+H57+H73+H89+H105+H121+H137+H153+H169+H185+H201+H217+H233+H249+H265+H281+H297+H313+H329+H345 -> 0 | I25: =I41+I57+I73+I89+I105+I121+I137+I153+I169+I185+I201+I217+I233+I249+I265+I281+I297+I313+I329+I345 -> 0 | ... U25: =U41+U57+U73+U89+U105+U121+U137+U153+U169+U185+U201+U217+U233+U249+U265+U281+U297+U313+U329+U345 -> 0 | W25: =W24+3 -> 21 | X25: =X41+X57+X73+X89+X105+X121+X137+X153+X169+X185+X201+X217+X233+X249+X265+X281+X297+X313+X329+X345 -> 0 | Y25: =Y41+Y57+Y73+Y89+Y105+Y121+Y137+Y153+Y169+Y185+Y201+Y217+Y233+Y249+Y265+Y281+Y297+Y313+Y329+Y345 -> 0 | Z25: =Z41+Z57+Z73+Z89+Z105+Z121+Z137+Z153+Z169+Z185+Z201+Z217+Z233+Z249+Z265+Z281+Z297+Z313+Z329+Z345 -> 0 | AA25: =AA41+AA57+AA73+AA89+AA105+AA121+AA137+AA153+AA169+AA185+AA201+AA217+AA233+AA249+AA265+AA281+AA297+AA313+AA329+AA345 -> 0 | AB25: =AB41+AB57+AB73+AB89+AB105+AB121+AB137+AB153+AB169+AB185+AB201+AB217+AB233+AB249+AB265+AB281+AB297+AB313+AB329+AB345 -> 0 | AC25: =AC41+AC57+AC73+AC89+AC105+AC121+AC137+AC153+AC169+AC185+AC201+AC217+AC233+AC249+AC265+AC281+AC297+AC313+AC329+AC345 -> 0 | AD25: =AD41+AD57+AD73+AD89+AD105+AD121+AD137+AD153+AD169+AD185+AD201+AD217+AD233+AD249+AD265+AD281+AD297+AD313+AD329+AD345 -> 0 | AE25: =AE41+AE57+AE73+AE89+AE105+AE121+AE137+AE153+AE169+AE185+AE201+AE217+AE233+AE249+AE265+AE281+AE297+AE313+AE329+AE345 -> 0 | ... AQ25: =AQ41+AQ57+AQ73+AQ89+AQ105+AQ121+AQ137+AQ153+AQ169+AQ185+AQ201+AQ217+AQ233+AQ249+AQ265+AQ281+AQ297+AQ313+AQ329+AQ345 -> 0
A26: =A25+3 -> 24 | B26: =B42+B58+B74+B90+B106+B122+B138+B154+B170+B186+B202+B218+B234+B250+B266+B282+B298+B314+B330+B346 -> 0 | C26: =C42+C58+C74+C90+C106+C122+C138+C154+C170+C186+C202+C218+C234+C250+C266+C282+C298+C314+C330+C346 -> 0 | D26: =D42+D58+D74+D90+D106+D122+D138+D154+D170+D186+D202+D218+D234+D250+D266+D282+D298+D314+D330+D346 -> 0 | E26: =E42+E58+E74+E90+E106+E122+E138+E154+E170+E186+E202+E218+E234+E250+E266+E282+E298+E314+E330+E346 -> 0 | F26: =F42+F58+F74+F90+F106+F122+F138+F154+F170+F186+F202+F218+F234+F250+F266+F282+F298+F314+F330+F346 -> 0 | G26: =G42+G58+G74+G90+G106+G122+G138+G154+G170+G186+G202+G218+G234+G250+G266+G282+G298+G314+G330+G346 -> 0 | H26: =H42+H58+H74+H90+H106+H122+H138+H154+H170+H186+H202+H218+H234+H250+H266+H282+H298+H314+H330+H346 -> 0 | I26: =I42+I58+I74+I90+I106+I122+I138+I154+I170+I186+I202+I218+I234+I250+I266+I282+I298+I314+I330+I346 -> 0 | ... U26: =U42+U58+U74+U90+U106+U122+U138+U154+U170+U186+U202+U218+U234+U250+U266+U282+U298+U314+U330+U346 -> 0 | W26: =W25+3 -> 24 | X26: =X42+X58+X74+X90+X106+X122+X138+X154+X170+X186+X202+X218+X234+X250+X266+X282+X298+X314+X330+X346 -> 0 | Y26: =Y42+Y58+Y74+Y90+Y106+Y122+Y138+Y154+Y170+Y186+Y202+Y218+Y234+Y250+Y266+Y282+Y298+Y314+Y330+Y346 -> 0 | Z26: =Z42+Z58+Z74+Z90+Z106+Z122+Z138+Z154+Z170+Z186+Z202+Z218+Z234+Z250+Z266+Z282+Z298+Z314+Z330+Z346 -> 0 | AA26: =AA42+AA58+AA74+AA90+AA106+AA122+AA138+AA154+AA170+AA186+AA202+AA218+AA234+AA250+AA266+AA282+AA298+AA314+AA330+AA346 -> 0 | AB26: =AB42+AB58+AB74+AB90+AB106+AB122+AB138+AB154+AB170+AB186+AB202+AB218+AB234+AB250+AB266+AB282+AB298+AB314+AB330+AB346 -> 0 | AC26: =AC42+AC58+AC74+AC90+AC106+AC122+AC138+AC154+AC170+AC186+AC202+AC218+AC234+AC250+AC266+AC282+AC298+AC314+AC330+AC346 -> 0 | AD26: =AD42+AD58+AD74+AD90+AD106+AD122+AD138+AD154+AD170+AD186+AD202+AD218+AD234+AD250+AD266+AD282+AD298+AD314+AD330+AD346 -> 0 | AE26: =AE42+AE58+AE74+AE90+AE106+AE122+AE138+AE154+AE170+AE186+AE202+AE218+AE234+AE250+AE266+AE282+AE298+AE314+AE330+AE346 -> 0 | ... AQ26: =AQ42+AQ58+AQ74+AQ90+AQ106+AQ122+AQ138+AQ154+AQ170+AQ186+AQ202+AQ218+AQ234+AQ250+AQ266+AQ282+AQ298+AQ314+AQ330+AQ346 -> 0
A27: =A26+3 -> 27 | B27: =B43+B59+B75+B91+B107+B123+B139+B155+B171+B187+B203+B219+B235+B251+B267+B283+B299+B315+B331+B347 -> 0 | C27: =C43+C59+C75+C91+C107+C123+C139+C155+C171+C187+C203+C219+C235+C251+C267+C283+C299+C315+C331+C347 -> 0 | D27: =D43+D59+D75+D91+D107+D123+D139+D155+D171+D187+D203+D219+D235+D251+D267+D283+D299+D315+D331+D347 -> 0 | E27: =E43+E59+E75+E91+E107+E123+E139+E155+E171+E187+E203+E219+E235+E251+E267+E283+E299+E315+E331+E347 -> 0 | F27: =F43+F59+F75+F91+F107+F123+F139+F155+F171+F187+F203+F219+F235+F251+F267+F283+F299+F315+F331+F347 -> 0 | G27: =G43+G59+G75+G91+G107+G123+G139+G155+G171+G187+G203+G219+G235+G251+G267+G283+G299+G315+G331+G347 -> 0 | H27: =H43+H59+H75+H91+H107+H123+H139+H155+H171+H187+H203+H219+H235+H251+H267+H283+H299+H315+H331+H347 -> 0 | I27: =I43+I59+I75+I91+I107+I123+I139+I155+I171+I187+I203+I219+I235+I251+I267+I283+I299+I315+I331+I347 -> 0 | ... U27: =U43+U59+U75+U91+U107+U123+U139+U155+U171+U187+U203+U219+U235+U251+U267+U283+U299+U315+U331+U347 -> 0 | W27: =W26+3 -> 27 | X27: =X43+X59+X75+X91+X107+X123+X139+X155+X171+X187+X203+X219+X235+X251+X267+X283+X299+X315+X331+X347 -> 0 | Y27: =Y43+Y59+Y75+Y91+Y107+Y123+Y139+Y155+Y171+Y187+Y203+Y219+Y235+Y251+Y267+Y283+Y299+Y315+Y331+Y347 -> 0 | Z27: =Z43+Z59+Z75+Z91+Z107+Z123+Z139+Z155+Z171+Z187+Z203+Z219+Z235+Z251+Z267+Z283+Z299+Z315+Z331+Z347 -> 0 | AA27: =AA43+AA59+AA75+AA91+AA107+AA123+AA139+AA155+AA171+AA187+AA203+AA219+AA235+AA251+AA267+AA283+AA299+AA315+AA331+AA347 -> 0 | AB27: =AB43+AB59+AB75+AB91+AB107+AB123+AB139+AB155+AB171+AB187+AB203+AB219+AB235+AB251+AB267+AB283+AB299+AB315+AB331+AB347 -> 0 | AC27: =AC43+AC59+AC75+AC91+AC107+AC123+AC139+AC155+AC171+AC187+AC203+AC219+AC235+AC251+AC267+AC283+AC299+AC315+AC331+AC347 -> 0 | AD27: =AD43+AD59+AD75+AD91+AD107+AD123+AD139+AD155+AD171+AD187+AD203+AD219+AD235+AD251+AD267+AD283+AD299+AD315+AD331+AD347 -> 0 | AE27: =AE43+AE59+AE75+AE91+AE107+AE123+AE139+AE155+AE171+AE187+AE203+AE219+AE235+AE251+AE267+AE283+AE299+AE315+AE331+AE347 -> 0 | ... AQ27: =AQ43+AQ59+AQ75+AQ91+AQ107+AQ123+AQ139+AQ155+AQ171+AQ187+AQ203+AQ219+AQ235+AQ251+AQ267+AQ283+AQ299+AQ315+AQ331+AQ347 -> 0
A28: CQ NEP | B28: =B44+B60+B76+B92+B108+B124+B140+B156+B172+B188+B204+B220+B236+B252+B268+B284+B300+B316+B332+B348 -> 2398.4375 | C28: =C44+C60+C76+C92+C108+C124+C140+C156+C172+C188+C204+C220+C236+C252+C268+C284+C300+C316+C332+C348 -> 4070.3125 | D28: =D44+D60+D76+D92+D108+D124+D140+D156+D172+D188+D204+D220+D236+D252+D268+D284+D300+D316+D332+D348 -> 4460.9375 | E28: =E44+E60+E76+E92+E108+E124+E140+E156+E172+E188+E204+E220+E236+E252+E268+E284+E300+E316+E332+E348 -> 4695.3125 | F28: =F44+F60+F76+F92+F108+F124+F140+F156+F172+F188+F204+F220+F236+F252+F268+F284+F300+F316+F332+F348 -> 5659.375 | G28: =G44+G60+G76+G92+G108+G124+G140+G156+G172+G188+G204+G220+G236+G252+G268+G284+G300+G316+G332+G348 -> 6553.125 | H28: =H44+H60+H76+H92+H108+H124+H140+H156+H172+H188+H204+H220+H236+H252+H268+H284+H300+H316+H332+H348 -> 7084.375 | I28: =I44+I60+I76+I92+I108+I124+I140+I156+I172+I188+I204+I220+I236+I252+I268+I284+I300+I316+I332+I348 -> 7553.125 | ... U28: =U44+U60+U76+U92+U108+U124+U140+U156+U172+U188+U204+U220+U236+U252+U268+U284+U300+U316+U332+U348 -> 20310.938 | W28: CQ GEP | X28: =X44+X60+X76+X92+X108+X124+X140+X156+X172+X188+X204+X220+X236+X252+X268+X284+X300+X316+X332+X348 -> 4140.625 | Y28: =Y44+Y60+Y76+Y92+Y108+Y124+Y140+Y156+Y172+Y188+Y204+Y220+Y236+Y252+Y268+Y284+Y300+Y316+Y332+Y348 -> 8796.875 | Z28: =Z44+Z60+Z76+Z92+Z108+Z124+Z140+Z156+Z172+Z188+Z204+Z220+Z236+Z252+Z268+Z284+Z300+Z316+Z332+Z348 -> 11515.625 | AA28: =AA44+AA60+AA76+AA92+AA108+AA124+AA140+AA156+AA172+AA188+AA204+AA220+AA236+AA252+AA268+AA284+AA300+AA316+AA332+AA348 -> 13921.875 | AB28: =AB44+AB60+AB76+AB92+AB108+AB124+AB140+AB156+AB172+AB188+AB204+AB220+AB236+AB252+AB268+AB284+AB300+AB316+AB332+AB348 -> 17468.75 | AC28: =AC44+AC60+AC76+AC92+AC108+AC124+AC140+AC156+AC172+AC188+AC204+AC220+AC236+AC252+AC268+AC284+AC300+AC316+AC332+AC348 -> 21156.25 | AD28: =AD44+AD60+AD76+AD92+AD108+AD124+AD140+AD156+AD172+AD188+AD204+AD220+AD236+AD252+AD268+AD284+AD300+AD316+AD332+AD348 -> 24218.75 | AE28: =AE44+AE60+AE76+AE92+AE108+AE124+AE140+AE156+AE172+AE188+AE204+AE220+AE236+AE252+AE268+AE284+AE300+AE316+AE332+AE348 -> 27156.25 | ... AQ28: =AQ44+AQ60+AQ76+AQ92+AQ108+AQ124+AQ140+AQ156+AQ172+AQ188+AQ204+AQ220+AQ236+AQ252+AQ268+AQ284+AQ300+AQ316+AQ332+AQ348 -> 96234.375
A29: CQ Ceded EP | B29: =X28-B28 -> 1742.1875 | C29: =Y28-C28 -> 4726.5625 | D29: =Z28-D28 -> 7054.6875 | E29: =AA28-E28 -> 9226.5625 | F29: =AB28-F28 -> 11809.375 | G29: =AC28-G28 -> 14603.125 | H29: =AD28-H28 -> 17134.375 | I29: =AE28-I28 -> 19603.125 | ... U29: =AQ28-U28 -> 75923.438
A31: P001 | B31: =INDEX('Program Inputs'!$B$9:$B$28,MATCH('Prem Earn'!A31,'Program Inputs'!$A$9:$A$28,0)) -> VI: Sports Refund | W31: P001 | X31: =INDEX('Program Inputs'!$B$9:$B$28,MATCH('Prem Earn'!W31,'Program Inputs'!$A$9:$A$28,0)) -> VI: Sports Refund
A32: Net Earned Premium | W32: Gross Earned Premium
A33: Policy Length | B33: =INDEX('Program Inputs'!$N$8:$N$28,MATCH(A31,'Program Inputs'!$A$8:$A$28,0)) -> 2 | W33: Policy Length | X33: =INDEX('Program Inputs'!$N$8:$N$28,MATCH(W31,'Program Inputs'!$A$8:$A$28,0)) -> 2
A34: Age | B34: ='Program Qtrly'!D$6 -> 2026 Q2 | C34: ='Program Qtrly'!E$6 -> 2026 Q3 | D34: ='Program Qtrly'!F$6 -> 2026 Q4 | E34: ='Program Qtrly'!G$6 -> 2027 Q1 | F34: ='Program Qtrly'!H$6 -> 2027 Q2 | G34: ='Program Qtrly'!I$6 -> 2027 Q3 | H34: ='Program Qtrly'!J$6 -> 2027 Q4 | I34: ='Program Qtrly'!K$6 -> 2028 Q1 | ... U34: ='Program Qtrly'!W$6 -> 2031 Q1 | W34: Age | X34: ='Program Qtrly'!D$6 -> 2026 Q2 | Y34: ='Program Qtrly'!E$6 -> 2026 Q3 | Z34: ='Program Qtrly'!F$6 -> 2026 Q4 | AA34: ='Program Qtrly'!G$6 -> 2027 Q1 | AB34: ='Program Qtrly'!H$6 -> 2027 Q2 | AC34: ='Program Qtrly'!I$6 -> 2027 Q3 | AD34: ='Program Qtrly'!J$6 -> 2027 Q4 | AE34: ='Program Qtrly'!K$6 -> 2028 Q1 | ... AQ34: ='Program Qtrly'!W$6 -> 2031 Q1
A35: 3 | B35: =IFERROR('Program Qtrly'!D$15*OFFSET('Prem Earn'!$A$5,MATCH($B$33,'Prem Earn'!$A$6:$A$12,0),MATCH($A35,'Prem Earn'!$B$5:$J$5,0)),0) -> 2000 | C35: =IFERROR('Program Qtrly'!E$15*OFFSET('Prem Earn'!$A$5,MATCH($B$33,'Prem Earn'!$A$6:$A$12,0),MATCH($A35,'Prem Earn'!$B$5:$J$5,0)),0) -> 2000 | D35: =IFERROR('Program Qtrly'!F$15*OFFSET('Prem Earn'!$A$5,MATCH($B$33,'Prem Earn'!$A$6:$A$12,0),MATCH($A35,'Prem Earn'!$B$5:$J$5,0)),0) -> 2000 | E35: =IFERROR('Program Qtrly'!G$15*OFFSET('Prem Earn'!$A$5,MATCH($B$33,'Prem Earn'!$A$6:$A$12,0),MATCH($A35,'Prem Earn'!$B$5:$J$5,0)),0) -> 2000 | F35: =IFERROR('Program Qtrly'!H$15*OFFSET('Prem Earn'!$A$5,MATCH($B$33,'Prem Earn'!$A$6:$A$12,0),MATCH($A35,'Prem Earn'!$B$5:$J$5,0)),0) -> 2500 | G35: =IFERROR('Program Qtrly'!I$15*OFFSET('Prem Earn'!$A$5,MATCH($B$33,'Prem Earn'!$A$6:$A$12,0),MATCH($A35,'Prem Earn'!$B$5:$J$5,0)),0) -> 2500 | H35: =IFERROR('Program Qtrly'!J$15*OFFSET('Prem Earn'!$A$5,MATCH($B$33,'Prem Earn'!$A$6:$A$12,0),MATCH($A35,'Prem Earn'!$B$5:$J$5,0)),0) -> 2500 | I35: =IFERROR('Program Qtrly'!K$15*OFFSET('Prem Earn'!$A$5,MATCH($B$33,'Prem Earn'!$A$6:$A$12,0),MATCH($A35,'Prem Earn'!$B$5:$J$5,0)),0) -> 2500 | ... U35: =IFERROR('Program Qtrly'!W$15*OFFSET('Prem Earn'!$A$5,MATCH($B$33,'Prem Earn'!$A$6:$A$12,0),MATCH($A35,'Prem Earn'!$B$5:$J$5,0)),0) -> 4000 | W35: 3 | X35: =IFERROR('Program Qtrly'!D$7*OFFSET('Prem Earn'!$A$5,MATCH($B$33,'Prem Earn'!$A$6:$A$12,0),MATCH($A35,'Prem Earn'!$B$5:$J$5,0)),0) -> 2000 | Y35: =IFERROR('Program Qtrly'!E$7*OFFSET('Prem Earn'!$A$5,MATCH($B$33,'Prem Earn'!$A$6:$A$12,0),MATCH($A35,'Prem Earn'!$B$5:$J$5,0)),0) -> 2000 | Z35: =IFERROR('Program Qtrly'!F$7*OFFSET('Prem Earn'!$A$5,MATCH($B$33,'Prem Earn'!$A$6:$A$12,0),MATCH($A35,'Prem Earn'!$B$5:$J$5,0)),0) -> 2000 | AA35: =IFERROR('Program Qtrly'!G$7*OFFSET('Prem Earn'!$A$5,MATCH($B$33,'Prem Earn'!$A$6:$A$12,0),MATCH($A35,'Prem Earn'!$B$5:$J$5,0)),0) -> 2000 | AB35: =IFERROR('Program Qtrly'!H$7*OFFSET('Prem Earn'!$A$5,MATCH($B$33,'Prem Earn'!$A$6:$A$12,0),MATCH($A35,'Prem Earn'!$B$5:$J$5,0)),0) -> 2500 | AC35: =IFERROR('Program Qtrly'!I$7*OFFSET('Prem Earn'!$A$5,MATCH($B$33,'Prem Earn'!$A$6:$A$12,0),MATCH($A35,'Prem Earn'!$B$5:$J$5,0)),0) -> 2500 | AD35: =IFERROR('Program Qtrly'!J$7*OFFSET('Prem Earn'!$A$5,MATCH($B$33,'Prem Earn'!$A$6:$A$12,0),MATCH($A35,'Prem Earn'!$B$5:$J$5,0)),0) -> 2500 | AE35: =IFERROR('Program Qtrly'!K$7*OFFSET('Prem Earn'!$A$5,MATCH($B$33,'Prem Earn'!$A$6:$A$12,0),MATCH($A35,'Prem Earn'!$B$5:$J$5,0)),0) -> 2500 | ... AQ35: =IFERROR('Program Qtrly'!W$7*OFFSET('Prem Earn'!$A$5,MATCH($B$33,'Prem Earn'!$A$6:$A$12,0),MATCH($A35,'Prem Earn'!$B$5:$J$5,0)),0) -> 4000
A36: =A35+3 -> 6 | B36: =IFERROR('Program Qtrly'!D$15*OFFSET('Prem Earn'!$A$5,MATCH($B$33,'Prem Earn'!$A$6:$A$12,0),MATCH($A36,'Prem Earn'!$B$5:$J$5,0)),0) -> 1000 | C36: =IFERROR('Program Qtrly'!E$15*OFFSET('Prem Earn'!$A$5,MATCH($B$33,'Prem Earn'!$A$6:$A$12,0),MATCH($A36,'Prem Earn'!$B$5:$J$5,0)),0) -> 1000 | D36: =IFERROR('Program Qtrly'!F$15*OFFSET('Prem Earn'!$A$5,MATCH($B$33,'Prem Earn'!$A$6:$A$12,0),MATCH($A36,'Prem Earn'!$B$5:$J$5,0)),0) -> 1000 | E36: =IFERROR('Program Qtrly'!G$15*OFFSET('Prem Earn'!$A$5,MATCH($B$33,'Prem Earn'!$A$6:$A$12,0),MATCH($A36,'Prem Earn'!$B$5:$J$5,0)),0) -> 1000 | F36: =IFERROR('Program Qtrly'!H$15*OFFSET('Prem Earn'!$A$5,MATCH($B$33,'Prem Earn'!$A$6:$A$12,0),MATCH($A36,'Prem Earn'!$B$5:$J$5,0)),0) -> 1250 | G36: =IFERROR('Program Qtrly'!I$15*OFFSET('Prem Earn'!$A$5,MATCH($B$33,'Prem Earn'!$A$6:$A$12,0),MATCH($A36,'Prem Earn'!$B$5:$J$5,0)),0) -> 1250 | H36: =IFERROR('Program Qtrly'!J$15*OFFSET('Prem Earn'!$A$5,MATCH($B$33,'Prem Earn'!$A$6:$A$12,0),MATCH($A36,'Prem Earn'!$B$5:$J$5,0)),0) -> 1250 | I36: =IFERROR('Program Qtrly'!K$15*OFFSET('Prem Earn'!$A$5,MATCH($B$33,'Prem Earn'!$A$6:$A$12,0),MATCH($A36,'Prem Earn'!$B$5:$J$5,0)),0) -> 1250 | ... U36: =IFERROR('Program Qtrly'!W$15*OFFSET('Prem Earn'!$A$5,MATCH($B$33,'Prem Earn'!$A$6:$A$12,0),MATCH($A36,'Prem Earn'!$B$5:$J$5,0)),0) -> 2000 | W36: =W35+3 -> 6 | X36: =IFERROR('Program Qtrly'!D$7*OFFSET('Prem Earn'!$A$5,MATCH($B$33,'Prem Earn'!$A$6:$A$12,0),MATCH($A36,'Prem Earn'!$B$5:$J$5,0)),0) -> 1000 | Y36: =IFERROR('Program Qtrly'!E$7*OFFSET('Prem Earn'!$A$5,MATCH($B$33,'Prem Earn'!$A$6:$A$12,0),MATCH($A36,'Prem Earn'!$B$5:$J$5,0)),0) -> 1000 | Z36: =IFERROR('Program Qtrly'!F$7*OFFSET('Prem Earn'!$A$5,MATCH($B$33,'Prem Earn'!$A$6:$A$12,0),MATCH($A36,'Prem Earn'!$B$5:$J$5,0)),0) -> 1000 | AA36: =IFERROR('Program Qtrly'!G$7*OFFSET('Prem Earn'!$A$5,MATCH($B$33,'Prem Earn'!$A$6:$A$12,0),MATCH($A36,'Prem Earn'!$B$5:$J$5,0)),0) -> 1000 | AB36: =IFERROR('Program Qtrly'!H$7*OFFSET('Prem Earn'!$A$5,MATCH($B$33,'Prem Earn'!$A$6:$A$12,0),MATCH($A36,'Prem Earn'!$B$5:$J$5,0)),0) -> 1250 | AC36: =IFERROR('Program Qtrly'!I$7*OFFSET('Prem Earn'!$A$5,MATCH($B$33,'Prem Earn'!$A$6:$A$12,0),MATCH($A36,'Prem Earn'!$B$5:$J$5,0)),0) -> 1250 | AD36: =IFERROR('Program Qtrly'!J$7*OFFSET('Prem Earn'!$A$5,MATCH($B$33,'Prem Earn'!$A$6:$A$12,0),MATCH($A36,'Prem Earn'!$B$5:$J$5,0)),0) -> 1250 | AE36: =IFERROR('Program Qtrly'!K$7*OFFSET('Prem Earn'!$A$5,MATCH($B$33,'Prem Earn'!$A$6:$A$12,0),MATCH($A36,'Prem Earn'!$B$5:$J$5,0)),0) -> 1250 | ... AQ36: =IFERROR('Program Qtrly'!W$7*OFFSET('Prem Earn'!$A$5,MATCH($B$33,'Prem Earn'!$A$6:$A$12,0),MATCH($A36,'Prem Earn'!$B$5:$J$5,0)),0) -> 2000
A37: =A36+3 -> 9 | B37: =IFERROR('Program Qtrly'!D$15*OFFSET('Prem Earn'!$A$5,MATCH($B$33,'Prem Earn'!$A$6:$A$12,0),MATCH($A37,'Prem Earn'!$B$5:$J$5,0)),0) -> 0 | C37: =IFERROR('Program Qtrly'!E$15*OFFSET('Prem Earn'!$A$5,MATCH($B$33,'Prem Earn'!$A$6:$A$12,0),MATCH($A37,'Prem Earn'!$B$5:$J$5,0)),0) -> 0 | D37: =IFERROR('Program Qtrly'!F$15*OFFSET('Prem Earn'!$A$5,MATCH($B$33,'Prem Earn'!$A$6:$A$12,0),MATCH($A37,'Prem Earn'!$B$5:$J$5,0)),0) -> 0 | E37: =IFERROR('Program Qtrly'!G$15*OFFSET('Prem Earn'!$A$5,MATCH($B$33,'Prem Earn'!$A$6:$A$12,0),MATCH($A37,'Prem Earn'!$B$5:$J$5,0)),0) -> 0 | F37: =IFERROR('Program Qtrly'!H$15*OFFSET('Prem Earn'!$A$5,MATCH($B$33,'Prem Earn'!$A$6:$A$12,0),MATCH($A37,'Prem Earn'!$B$5:$J$5,0)),0) -> 0 | G37: =IFERROR('Program Qtrly'!I$15*OFFSET('Prem Earn'!$A$5,MATCH($B$33,'Prem Earn'!$A$6:$A$12,0),MATCH($A37,'Prem Earn'!$B$5:$J$5,0)),0) -> 0 | H37: =IFERROR('Program Qtrly'!J$15*OFFSET('Prem Earn'!$A$5,MATCH($B$33,'Prem Earn'!$A$6:$A$12,0),MATCH($A37,'Prem Earn'!$B$5:$J$5,0)),0) -> 0 | I37: =IFERROR('Program Qtrly'!K$15*OFFSET('Prem Earn'!$A$5,MATCH($B$33,'Prem Earn'!$A$6:$A$12,0),MATCH($A37,'Prem Earn'!$B$5:$J$5,0)),0) -> 0 | ... U37: =IFERROR('Program Qtrly'!W$15*OFFSET('Prem Earn'!$A$5,MATCH($B$33,'Prem Earn'!$A$6:$A$12,0),MATCH($A37,'Prem Earn'!$B$5:$J$5,0)),0) -> 0 | W37: =W36+3 -> 9 | X37: =IFERROR('Program Qtrly'!D$7*OFFSET('Prem Earn'!$A$5,MATCH($B$33,'Prem Earn'!$A$6:$A$12,0),MATCH($A37,'Prem Earn'!$B$5:$J$5,0)),0) -> 0 | Y37: =IFERROR('Program Qtrly'!E$7*OFFSET('Prem Earn'!$A$5,MATCH($B$33,'Prem Earn'!$A$6:$A$12,0),MATCH($A37,'Prem Earn'!$B$5:$J$5,0)),0) -> 0 | Z37: =IFERROR('Program Qtrly'!F$7*OFFSET('Prem Earn'!$A$5,MATCH($B$33,'Prem Earn'!$A$6:$A$12,0),MATCH($A37,'Prem Earn'!$B$5:$J$5,0)),0) -> 0 | AA37: =IFERROR('Program Qtrly'!G$7*OFFSET('Prem Earn'!$A$5,MATCH($B$33,'Prem Earn'!$A$6:$A$12,0),MATCH($A37,'Prem Earn'!$B$5:$J$5,0)),0) -> 0 | AB37: =IFERROR('Program Qtrly'!H$7*OFFSET('Prem Earn'!$A$5,MATCH($B$33,'Prem Earn'!$A$6:$A$12,0),MATCH($A37,'Prem Earn'!$B$5:$J$5,0)),0) -> 0 | AC37: =IFERROR('Program Qtrly'!I$7*OFFSET('Prem Earn'!$A$5,MATCH($B$33,'Prem Earn'!$A$6:$A$12,0),MATCH($A37,'Prem Earn'!$B$5:$J$5,0)),0) -> 0 | AD37: =IFERROR('Program Qtrly'!J$7*OFFSET('Prem Earn'!$A$5,MATCH($B$33,'Prem Earn'!$A$6:$A$12,0),MATCH($A37,'Prem Earn'!$B$5:$J$5,0)),0) -> 0 | AE37: =IFERROR('Program Qtrly'!K$7*OFFSET('Prem Earn'!$A$5,MATCH($B$33,'Prem Earn'!$A$6:$A$12,0),MATCH($A37,'Prem Earn'!$B$5:$J$5,0)),0) -> 0 | ... AQ37: =IFERROR('Program Qtrly'!W$7*OFFSET('Prem Earn'!$A$5,MATCH($B$33,'Prem Earn'!$A$6:$A$12,0),MATCH($A37,'Prem Earn'!$B$5:$J$5,0)),0) -> 0
